<?xml version="1.0"?>
<!-- created with Phobos 1.0.1 "Capricious Choutengan" -->
<robot name="base" xmlns:xacro="http://wiki.ros.org/xacro">

  <xacro:macro name="wheel" params="prefix parent xyz rpy">
    <link name="${prefix}_link">
      <collision name="${prefix}_collision">
          <origin rpy="0.00000 0.00000 0.00000" xyz="0.00000 0.00000 0.00000"/>
          <geometry>
              <mesh filename="file://$(find roverto_description)/dae/Cilindro.005.dae" scale="0.30000 0.30000 0.10000"/>   
          </geometry>
          </collision>
          <inertial>
              <inertia ixx="1.17477" ixy="0.00000" ixz="-0.00000" iyy="0.62554" iyz="-0.00000" izz="0.62554"/>
              <origin rpy="0.00000 0.00000 0.00000" xyz="0.00000 0.00000 -0.01040"/>
              <mass value="15.00000"/>
          </inertial>
          <visual name="${prefix}">
              <origin rpy="0.00000 -0.00000 0.00000" xyz="0.00000 0.00000 0.00000"/>
              <geometry>
                  <mesh filename="file://$(find roverto_description)/dae/Cilindro.005.dae" scale="0.30000 0.30000 0.10000"/>
              </geometry>
          </visual>
    </link>

    <joint name="${prefix}_wheel_joint" type="continuous">
      <limit lower="0" upper="0" effort="0.00000" velocity="0.00000"/>
      <origin xyz="${xyz}" rpy="${rpy}"/>
      <parent link="${parent}"/>
      <child link="${prefix}_link"/>
      <axis xyz="0.00000 0.00000 1.00000"/>
    </joint>
  </xacro:macro>

  <xacro:macro name="wheels" params="parent">
    <!-- Seis ruedas -->
    <xacro:wheel prefix="right_front" parent="${parent}" xyz="-0.95 -1.20045 -0.54704" rpy="1.5708 0.0 -1.5708"/>
    <xacro:wheel prefix="right_mid" parent="${parent}" xyz="-0.95 0.29955 -0.54704" rpy="1.5708 0.0 -1.5708"/>
    <xacro:wheel prefix="right_back" parent="${parent}" xyz="-0.95 1.49955 -0.54704" rpy="1.5708 0.0 -1.5708"/>
    <xacro:wheel prefix="left_front" parent="${parent}" xyz="0.97 -1.20045 -0.54704" rpy="1.5708 3.14 1.5708"/>
    <xacro:wheel prefix="left_mid" parent="${parent}" xyz="0.95 0.29955 -0.54704" rpy="1.5708 3.14 1.5708"/>
    <xacro:wheel prefix="left_back" parent="${parent}" xyz="0.95 1.49955 -0.54704" rpy="1.5708 3.14 1.5708"/>
  </xacro:macro>

</robot>
