<robot name="rover_scara" version="1.0">
  <joint name="Finger1_link_joint" type="prismatic">
    <limit lower="0.00000" upper="0.25000" effort="0.00000" velocity="0.00000"/>
    <origin rpy="-0.00000 1.57080 0.00000" xyz="-0.32000 0.00000 -0.20000"/>
    <parent link="Seg4_link"/>
    <child link="Finger1_link"/>
    <axis xyz="0.00000 0.00000 1.00000"/>
  </joint>
  <joint name="Finger2_link_joint" type="prismatic">
    <limit lower="0.00000" upper="0.25000" effort="0.00000" velocity="0.00000"/>
    <origin rpy="0.00000 -1.57080 0.00000" xyz="0.32000 0.00000 -0.20000"/>
    <parent link="Seg4_link"/>
    <child link="Finger2_link"/>
    <axis xyz="0.00000 0.00000 1.00000"/>
  </joint>
  <joint name="Seg1_link_joint" type="revolute">
    <limit lower="-6.00000" upper="6.00000" effort="0.00000" velocity="0.00000"/>
    <origin rpy="0.00000 0.00000 0.00000" xyz="0.00000 0.02000 1.60000"/>
    <parent link="base_brazo_link"/>
    <child link="Seg1_link"/>
    <axis xyz="0.00000 0.00000 1.00000"/>
  </joint>
  <joint name="Seg2_link_joint" type="revolute">
    <limit lower="-0.70000" upper="4.00000" effort="0.00000" velocity="0.00000"/>
    <origin rpy="0.00000 0.00000 0.00000" xyz="-0.00000 1.48000 -0.17250"/>
    <parent link="Seg1_link"/>
    <child link="Seg2_link"/>
    <axis xyz="0.00000 0.00000 1.00000"/>
  </joint>
  <joint name="Seg3_link_joint" type="prismatic">
    <limit lower="-2.50000" upper="0.00000" effort="0.00000" velocity="0.00000"/>
    <origin rpy="0.00000 0.00000 0.00000" xyz="1.80000 -0.00000 1.17250"/>
    <parent link="Seg2_link"/>
    <child link="Seg3_link"/>
    <axis xyz="0.00000 0.00000 1.00000"/>
  </joint>
  <joint name="Seg4_link_joint" type="continuous">
    <limit lower="0" upper="0" effort="0.00000" velocity="0.00000"/>
    <origin rpy="0.00000 0.00000 0.00000" xyz="-0.00000 -0.00000 -1.60000"/>
    <parent link="Seg3_link"/>
    <child link="Seg4_link"/>
    <axis xyz="0.00000 0.00000 1.00000"/>
  </joint>
  <joint name="base_brazo_link_joint" type="fixed">
    <origin rpy="0.00000 0.00000 0.00000" xyz="-0.00000 -0.62045 0.90296"/>
    <parent link="Base_link"/>
    <child link="base_brazo_link"/>
  </joint>
  <joint name="left_back_link_joint" type="continuous">
    <limit lower="0" upper="0" effort="0.00000" velocity="0.00000"/>
    <origin rpy="-0.00000 1.57080 0.00000" xyz="0.95000 1.49955 -0.54704"/>
    <parent link="Base_link"/>
    <child link="left_back_link"/>
    <axis xyz="0.00000 0.00000 1.00000"/>
  </joint>
  <joint name="left_front_link_joint" type="continuous">
    <limit lower="0" upper="0" effort="0.00000" velocity="0.00000"/>
    <origin rpy="0.00000 1.57080 0.00000" xyz="0.97000 -1.20045 -0.54704"/>
    <parent link="Base_link"/>
    <child link="left_front_link"/>
    <axis xyz="0.00000 0.00000 1.00000"/>
  </joint>
  <joint name="left_mid_link_joint" type="continuous">
    <limit lower="0" upper="0" effort="0.00000" velocity="0.00000"/>
    <origin rpy="-0.00000 1.57080 0.00000" xyz="0.95000 0.29955 -0.54704"/>
    <parent link="Base_link"/>
    <child link="left_mid_link"/>
    <axis xyz="0.00000 0.00000 1.00000"/>
  </joint>
  <joint name="right_back_link_joint" type="continuous">
    <limit lower="0" upper="0" effort="0.00000" velocity="0.00000"/>
    <origin rpy="0.00000 1.57080 0.00000" xyz="-0.95000 1.49955 -0.54704"/>
    <parent link="Base_link"/>
    <child link="right_back_link"/>
    <axis xyz="0.00000 0.00000 1.00000"/>
  </joint>
  <joint name="right_front_link_joint" type="continuous">
    <limit lower="0" upper="0" effort="0.00000" velocity="0.00000"/>
    <origin rpy="0.00000 1.57080 0.00000" xyz="-0.95000 -1.20045 -0.54704"/>
    <parent link="Base_link"/>
    <child link="right_front_link"/>
    <axis xyz="0.00000 0.00000 1.00000"/>
  </joint>
  <joint name="right_mid_link_joint" type="continuous">
    <limit lower="0" upper="0" effort="0.00000" velocity="0.00000"/>
    <origin rpy="-0.00000 1.57080 0.00000" xyz="-0.95000 0.29955 -0.54704"/>
    <parent link="Base_link"/>
    <child link="right_mid_link"/>
    <axis xyz="0.00000 0.00000 1.00000"/>
  </joint>
  <link name="Base_link">
    <collision name="Base_collision">
      <origin rpy="0.00000 0.00000 0.00000" xyz="-0.00000 -0.00000 -0.00000"/>
      <geometry>
        <mesh filename="../meshes/dae/Cubo.dae" scale="0.75000 1.90000 0.07500"/>
      </geometry>
    </collision>
    <inertial>
      <inertia ixx="178.93889" ixy="-0.00000" ixz="-0.00000" iyy="51.49117" iyz="-22.08723" izz="189.25988"/>
      <origin rpy="0.00000 0.00000 0.00000" xyz="-0.00000 -0.00000 -0.00000"/>
      <mass value="150.00000"/>
    </inertial>
    <visual name="Base">
      <origin rpy="0.00000 0.00000 0.00000" xyz="-0.00000 -0.00000 -0.00000"/>
      <geometry>
        <mesh filename="../meshes/dae/Cubo.dae" scale="0.75000 1.90000 0.07500"/>
      </geometry>
    </visual>
  </link>
  <link name="Finger1_link">
    <collision name="Finger1_collision">
      <origin rpy="0.00000 -1.57080 0.00000" xyz="-0.00000 0.00000 0.00000"/>
      <geometry>
        <mesh filename="../meshes/dae/Cubo.013.dae" scale="0.02500 0.35000 0.17500"/>
      </geometry>
    </collision>
    <inertial>
      <inertia ixx="0.05104" ixy="0.00000" ixz="-0.00000" iyy="0.01042" iyz="0.00000" izz="0.04104"/>
      <origin rpy="0.00000 0.00000 0.00000" xyz="-0.00000 0.00000 0.00000"/>
      <mass value="1.00000"/>
    </inertial>
    <visual name="Finger1">
      <origin rpy="0.00000 -1.57080 0.00000" xyz="-0.00000 0.00000 0.00000"/>
      <geometry>
        <mesh filename="../meshes/dae/Cubo.013.dae" scale="0.02500 0.35000 0.17500"/>
      </geometry>
    </visual>
  </link>
  <link name="Finger2_link">
    <collision name="Finger2_collision">
      <origin rpy="-0.00000 1.57080 0.00000" xyz="0.00000 0.00000 -0.00000"/>
      <geometry>
        <mesh filename="../meshes/dae/Cubo.014.dae" scale="0.02500 0.35000 0.17500"/>
      </geometry>
    </collision>
    <inertial>
      <inertia ixx="0.05104" ixy="0.00000" ixz="0.00000" iyy="0.01042" iyz="0.00000" izz="0.04104"/>
      <origin rpy="0.00000 0.00000 0.00000" xyz="-0.00000 0.00000 -0.00000"/>
      <mass value="1.00000"/>
    </inertial>
    <visual name="Finger2">
      <origin rpy="-0.00000 1.57080 0.00000" xyz="0.00000 0.00000 -0.00000"/>
      <geometry>
        <mesh filename="../meshes/dae/Cubo.014.dae" scale="0.02500 0.35000 0.17500"/>
      </geometry>
    </visual>
  </link>
  <link name="Seg1_link">
    <collision name="Seg1_collision">
      <origin rpy="0.00000 0.00000 0.00000" xyz="-0.00000 0.73263 0.00000"/>
      <geometry>
        <mesh filename="../meshes/dae/Cilindro.008.dae" scale="0.40000 0.25263 0.10000"/>
      </geometry>
    </collision>
    <inertial>
      <inertia ixx="1.34348" ixy="0.00000" ixz="-0.00000" iyy="0.14027" iyz="0.00000" izz="1.46554"/>
      <origin rpy="0.00000 0.00000 0.00000" xyz="-0.00000 0.73263 0.00000"/>
      <mass value="3.00000"/>
    </inertial>
    <visual name="Seg1">
      <origin rpy="0.00000 0.00000 0.00000" xyz="0.00000 0.73263 0.00000"/>
      <geometry>
        <mesh filename="../meshes/dae/Cilindro.008.dae" scale="0.40000 0.25263 0.10000"/>
      </geometry>
    </visual>
  </link>
  <link name="Seg2_link">
    <collision name="Seg2_collision">
      <origin rpy="0.00000 0.00000 0.00000" xyz="0.79998 0.00000 0.00000"/>
      <geometry>
        <mesh filename="../meshes/dae/Cilindro.009.dae" scale="0.27692 0.30000 0.10000"/>
      </geometry>
    </collision>
    <inertial>
      <inertia ixx="0.09499" ixy="0.00000" ixz="0.05946" iyy="1.42088" iyz="0.00000" izz="1.46646"/>
      <origin rpy="0.00000 0.00000 0.00000" xyz="0.82302 0.00000 0.00061"/>
      <mass value="3.00000"/>
    </inertial>
    <visual name="Seg2">
      <origin rpy="0.00000 0.00000 0.00000" xyz="0.79998 0.00000 0.00000"/>
      <geometry>
        <mesh filename="../meshes/dae/Cilindro.009.dae" scale="0.27692 0.30000 0.10000"/>
      </geometry>
    </visual>
  </link>
  <link name="Seg3_link">
    <collision name="Seg3_collision">
      <origin rpy="0.00000 0.00000 0.00000" xyz="0.00000 0.00000 0.00000"/>
      <geometry>
        <mesh filename="../meshes/dae/Cilindro.007.dae" scale="0.20000 0.20000 1.60000"/>
      </geometry>
    </collision>
    <inertial>
      <inertia ixx="1.72654" ixy="-0.00000" ixz="0.00000" iyy="1.72654" iyz="0.00000" izz="0.03974"/>
      <origin rpy="0.00000 0.00000 0.00000" xyz="-0.00000 -0.00000 -0.00000"/>
      <mass value="2.00000"/>
    </inertial>
    <visual name="Seg3">
      <origin rpy="0.00000 0.00000 0.00000" xyz="0.00000 0.00000 -0.00000"/>
      <geometry>
        <mesh filename="../meshes/dae/Cilindro.007.dae" scale="0.20000 0.20000 1.60000"/>
      </geometry>
    </visual>
  </link>
  <link name="Seg4_link">
    <collision name="Seg4_collision">
      <origin rpy="0.00000 0.00000 0.00000" xyz="0.00000 0.00000 0.00000"/>
      <geometry>
        <mesh filename="../meshes/dae/Cubo.012.dae" scale="0.35000 0.35000 0.02500"/>
      </geometry>
    </collision>
    <inertial>
      <inertia ixx="0.04104" ixy="0.00000" ixz="0.00000" iyy="0.04104" iyz="0.00000" izz="0.08167"/>
      <origin rpy="0.00000 0.00000 0.00000" xyz="0.00000 0.00000 0.00000"/>
      <mass value="1.00000"/>
    </inertial>
    <visual name="Seg4">
      <origin rpy="0.00000 0.00000 0.00000" xyz="0.00000 0.00000 0.00000"/>
      <geometry>
        <mesh filename="../meshes/dae/Cubo.012.dae" scale="0.35000 0.35000 0.02500"/>
      </geometry>
    </visual>
  </link>
  <link name="base_brazo_link">
    <collision name="base_brazo_collision">
      <origin rpy="0.00000 0.00000 0.00000" xyz="0.00000 0.00000 0.00000"/>
      <geometry>
        <mesh filename="../meshes/dae/Cilindro.006.dae" scale="0.45000 0.45000 0.07826"/>
      </geometry>
    </collision>
    <inertial>
      <inertia ixx="8.14387" ixy="0.00000" ixz="0.00000" iyy="8.14387" iyz="0.00000" izz="0.62637"/>
      <origin rpy="0.00000 0.00000 0.00000" xyz="0.00000 -0.00000 0.00000"/>
      <mass value="10.00000"/>
    </inertial>
    <visual name="base_brazo">
      <origin rpy="0.00000 0.00000 0.00000" xyz="0.00000 0.00000 -0.00000"/>
      <geometry>
        <mesh filename="../meshes/dae/Cilindro.006.dae" scale="0.45000 0.45000 0.07826"/>
      </geometry>
    </visual>
  </link>
  <link name="left_back_link">
    <collision name="left_back_collision">
      <origin rpy="0.00000 0.00000 0.00000" xyz="0.00000 -0.05000 -0.00000"/>
      <geometry>
        <mesh filename="../meshes/dae/Cilindro.001.dae" scale="0.30000 0.30000 0.10000"/>
      </geometry>
    </collision>
    <inertial>
      <inertia ixx="1.17477" ixy="-0.00000" ixz="-0.00000" iyy="0.62554" iyz="-0.00000" izz="0.62554"/>
      <origin rpy="0.00000 0.00000 0.00000" xyz="0.00000 0.00000 0.01040"/>
      <mass value="15.00000"/>
    </inertial>
    <visual name="left_back">
      <origin rpy="0.00000 0.00000 0.00000" xyz="0.00000 0.00000 -0.00000"/>
      <geometry>
        <mesh filename="../meshes/dae/Cilindro.001.dae" scale="0.30000 0.30000 0.10000"/>
      </geometry>
    </visual>
  </link>
  <link name="left_front_link">
    <collision name="left_front_collision">
      <origin rpy="0.00000 0.00000 0.00000" xyz="-0.00000 0.00000 0.00000"/>
      <geometry>
        <mesh filename="../meshes/dae/Rosca.004.dae" scale="0.36000 0.36000 0.40000"/>
      </geometry>
    </collision>
    <inertial>
      <inertia ixx="1.17557" ixy="-0.00000" ixz="-0.00000" iyy="0.62572" iyz="-0.00000" izz="0.62572"/>
      <origin rpy="0.00000 0.00000 0.00000" xyz="0.00000 0.00000 -0.00960"/>
      <mass value="15.00000"/>
    </inertial>
    <visual name="left_front">
      <origin rpy="0.00000 -0.00000 0.00000" xyz="-0.00000 0.00000 0.00000"/>
      <geometry>
        <mesh filename="../meshes/dae/Rosca.004.dae" scale="0.36000 0.36000 0.40000"/>
      </geometry>
    </visual>
  </link>
  <link name="left_mid_link">
    <collision name="left_mid_collision">
      <origin rpy="0.00000 0.00000 0.00000" xyz="0.00000 -0.00000 -0.00000"/>
      <geometry>
        <mesh filename="../meshes/dae/Cilindro.004.dae" scale="0.30000 0.30000 0.10000"/>
      </geometry>
    </collision>
    <inertial>
      <inertia ixx="1.17477" ixy="-0.00000" ixz="-0.00000" iyy="0.62554" iyz="-0.00000" izz="0.62554"/>
      <origin rpy="0.00000 0.00000 0.00000" xyz="0.00000 -0.00000 0.01040"/>
      <mass value="15.00000"/>
    </inertial>
    <visual name="left_mid">
      <origin rpy="0.00000 0.00000 0.00000" xyz="0.00000 -0.00000 -0.00000"/>
      <geometry>
        <mesh filename="../meshes/dae/Cilindro.004.dae" scale="0.30000 0.30000 0.10000"/>
      </geometry>
    </visual>
  </link>
  <link name="right_back_link">
    <collision name="right_back_collision">
      <origin rpy="0.00000 0.00000 0.00000" xyz="0.00000 -0.00000 0.00000"/>
      <geometry>
        <mesh filename="../meshes/dae/Cilindro.dae" scale="0.30000 0.30000 0.10000"/>
      </geometry>
    </collision>
    <inertial>
      <inertia ixx="1.17477" ixy="0.00000" ixz="-0.00000" iyy="0.62554" iyz="-0.00000" izz="0.62554"/>
      <origin rpy="0.00000 0.00000 0.00000" xyz="0.00000 0.00000 -0.01040"/>
      <mass value="15.00000"/>
    </inertial>
    <visual name="right_back">
      <origin rpy="0.00000 0.00000 0.00000" xyz="0.00000 0.00000 -0.00000"/>
      <geometry>
        <mesh filename="../meshes/dae/Cilindro.dae" scale="0.30000 0.30000 0.10000"/>
      </geometry>
    </visual>
  </link>
  <link name="right_front_link">
    <collision name="right_front_collision">
      <origin rpy="0.00000 0.00000 0.00000" xyz="0.00000 0.00000 0.00000"/>
      <geometry>
        <mesh filename="../meshes/dae/Cilindro.002.dae" scale="0.30000 0.30000 0.10000"/>
      </geometry>
    </collision>
    <inertial>
      <inertia ixx="1.17477" ixy="0.00000" ixz="-0.00000" iyy="0.62554" iyz="-0.00000" izz="0.62554"/>
      <origin rpy="0.00000 0.00000 0.00000" xyz="0.00000 0.00000 -0.01040"/>
      <mass value="15.00000"/>
    </inertial>
    <visual name="right_front">
      <origin rpy="0.00000 0.00000 0.00000" xyz="0.00000 0.00000 -0.00000"/>
      <geometry>
        <mesh filename="../meshes/dae/Cilindro.002.dae" scale="0.30000 0.30000 0.10000"/>
      </geometry>
    </visual>
  </link>
  <link name="right_mid_link">
    <collision name="right_mid_collision">
      <origin rpy="0.00000 0.00000 0.00000" xyz="0.00000 0.00000 0.00000"/>
      <geometry>
        <mesh filename="../meshes/dae/Cilindro.005.dae" scale="0.30000 0.30000 0.10000"/>
      </geometry>
    </collision>
    <inertial>
      <inertia ixx="1.17477" ixy="0.00000" ixz="-0.00000" iyy="0.62554" iyz="-0.00000" izz="0.62554"/>
      <origin rpy="0.00000 0.00000 0.00000" xyz="0.00000 0.00000 -0.01040"/>
      <mass value="15.00000"/>
    </inertial>
    <visual name="right_mid">
      <origin rpy="0.00000 -0.00000 0.00000" xyz="0.00000 0.00000 0.00000"/>
      <geometry>
        <mesh filename="../meshes/dae/Cilindro.005.dae" scale="0.30000 0.30000 0.10000"/>
      </geometry>
    </visual>
  </link>
</robot>