<?xml version="1.0"?>
<robot name="l_figure">

<!-- Definición de Material -->
    <material name="blue">
        <color rgba="0.0 0.0 1.0 1.0"/>
    </material>
    
    <material name="white">
        <color rgba="1.0 1.0 1.0 1.0"/>
    </material>


<!-- Definicion de links del robot-->
    <link name="base_link">

        <inertial>
            <origin xyz="0.0 0.0 0.2"/>
            <mass value="100.0"/>
            <inertia ixx="1.0" ixy="0.0" ixz="0.0" iyy="1.0" iyz="0.0" izz="1.0"/>
        </inertial>

        <visual>
            <origin xyz="0.0 0.0 0.2"/>
            <geometry>
                <box size="0.6 0.6 0.4"/>
            </geometry>
            <material name="white"/>
        </visual>

        <collision>
            <origin xyz="0.0 0.0 0.2"/>
            <geometry>
                <box size="0.6 0.6 0.4"/>
            </geometry>
        </collision>

    </link>

    <link name="middle_link">
        <inertial>
            <origin rpy="0.0 0.0 0.0" xyz="0.0 0.0 0.7"/>
            <mass value="5.0"/>
            <inertia ixx="1.0" ixy="0.0" ixz="0.0" iyy="1.0" iyz="0.0" izz="1.0"/>
        </inertial>

        <visual>
            <origin rpy="0.0 0.0 0.0" xyz="0.0 0.0 0.7"/>
            <geometry>
                <box size="0.2 0.2 1.2"/>
            </geometry>
            <material name="blue"/>
        </visual>

        <collision>
            <origin rpy="0.0 0.0 0.0" xyz="0.0 0.0 0.7"/>
            <geometry>
                <box size="0.2 0.2 1.2"/>
            </geometry>
        </collision>
        
    </link>

    <link name="top_link">
        <inertial>
            <origin rpy="1.57 0.0 0.0" xyz="0.0 0.3 0.05"/>
            <mass value="1.0"/>
            <inertia ixx="1.0" ixy="0.0" ixz="0.0" iyy="1.0" iyz="0.0" izz="1.0"/>
        </inertial>
        
        <visual>
            <origin rpy="1.57 0.0 0.0" xyz="0.0 0.3 0.05"/>
            <geometry>
                <box size="0.2 0.2 0.6"/>
            </geometry>
            <material name="blue"/>
        </visual>

        <collision>
            <origin rpy="1.57 0.0 0.0" xyz="0.0 0.3 0.05"/>
            <geometry>
                <box size="0.2 0.2 0.6"/>
            </geometry>
        </collision>
        
    </link>

<!-- Definicion de joints del robot-->

    <joint name="base_to_middle_joint" type="fixed">
        <parent link="base_link"/>
        <child link="middle_link"/>

        <origin xyz="0.0 0.0 0.2"/>
    </joint>

    <joint name="middle_to_top_joint" type="revolute">
        <parent link="middle_link"/>
        <child link="top_link"/>
        <dynamics damping="0.0" friction="0.0001"/>

        <origin xyz="0.0 0.0 1.3"/>
        <axis xyz="0 0 1"/>
        
        <limit lower="-100.0" upper="100.0" effort="10.0" velocity="1.0"/>
    </joint>
    
</robot>