<?xml version="1.0"?>

<robot name="barrera">

<!-- Definición de Material -->
    <material name="red">
        <color rgba="1.0 0.0 0.0 1.0"/>
    </material>

<!-- Definicion de links -->
    <link name="base_link">
        
        <!-- <inertial>
            <origin xyz="0.0 0.0 0.0" rpy="0.0 0.0 0.0"/>
            <mass value="0.0"/>
            <inertia ixx="0.0" ixy="0.0" ixz="0.0" iyy="0.0" iyz="0.0" izz="0.0"/>
        </inertial> -->

        <visual>
            <origin xyz="0.0 0.0 0.5" rpy="0.0 0.0 0.0"/>
            <geometry>
                <cylinder radius="0.1" length="1.0"/>
            </geometry>
            <material name="red"/>
            
        </visual>

        <collision>
            <origin xyz="0.0 0.0 0.5" rpy="0.0 0.0 0.0"/>
            <geometry>
                <cylinder radius="0.1" length="1.0"/>
            </geometry>
            
        </collision>
    </link>

    <link name="barrier_link">
        <!-- <inertial>
            <origin xyz="0.5 0.0 0.25" rpy="0.0 0.0 0.0"/>
            <mass value="5.0"/>
            <inertia ixx="0.0" ixy="0.0" ixz="0.0" iyy="0.0" iyz="0.0" izz="0.0"/>
        </inertial> -->

        <visual>
            <origin xyz="0.75 0.0 0.25" rpy="0.0 0.0 0.0"/>
            <geometry>
                <box size="1.5 0.1 0.1"/>
            </geometry>
            <material name="red"/>
        </visual>

        <collision>
            <origin xyz="0.5 0.0 0.25" rpy="0.0 0.0 0.0"/>
            <geometry>
                <box size="1.0 0.1 0.1"/>
            </geometry>
            
        </collision>
    </link>

<!-- Definicion Joints -->
    <joint name="barrier_joint" type="continuous">
        <origin xyz="0.0 0.0 0.25" rpy="0.0 0.0 0.0"/>
        <parent link="base_link"/>
        <child link="barrier_link"/>

        <axis xyz="0 0 1"/>

    </joint>
    
</robot>
